Workbook

Sheet PERSONAL BUDGET 2022-2023
A1: 2022 | B1: AUGUST | C1: SEPTEMBER | D1: OCTOBER | E1: NOVEMBER | F1: DECEMBER | G1: JANUARY | H1: FEBURARY | I1: MARCH | J1: APRIL | K1: MAY | L1: JUNE | M1: JULY | O1: TOTAL
A3: RENT | B3: 650 | O3: =SUM(B3:M3) -> 650
A4: STUDIO RENT | O4: =SUM(B4:M4) -> 0
A5: COUNCIL TAX | B5: 200 | F5: 200 | O5: =SUM(B5:M5) -> 400
A6: TOTAL | B6: =SUM(B3:B5) -> 850 | C6: =SUM(C3:C5) -> 0 | D6: =SUM(D3:D5) -> 0 | E6: =SUM(E3:E5) -> 0 | F6: =SUM(F3:F5) -> 200 | G6: =SUM(G3:G5) -> 0 | H6: =SUM(H3:H5) -> 0 | I6: =SUM(I3:I5) -> 0 | ... M6: =SUM(M3:M5) -> 0 | O6: =SUM(B6:M6) -> 1050
A7: EE | B7: 90 | C7: 90 | D7: 90 | E7: 90 | F7: 90 | G7: 90 | H7: 90 | O7: =SUM(B7:M7) -> 630
A8: VIRGIN | B8: 105 | C8: 105 | D8: 105 | E8: 105 | F8: 105 | G8: 105 | H8: 105 | O8: =SUM(B8:M8) -> 735
A9: ELECTRICITY | B9: 175 | C9: 175 | D9: 175 | E9: 175 | F9: 175 | G9: 175 | H9: 175
A10: ECLECTRICITY ARREARS | B10: 300 | C10: 300 | D10: 300 | E10: 300 | F10: 300 | G10: 300 | H10: 300 | L10: 300 | O10: =SUM(B10:M10) -> 2400
A11: LIFE INSURANCE | B11: 15 | C11: 15 | D11: 15 | E11: 15 | F11: 15 | G11: 15 | H11: 15 | O11: =SUM(B11:M11) -> 105
A12: TOTAL | B12: =SUM(B7:B11) -> 685 | C12: =SUM(C7:C11) -> 685 | D12: =SUM(D7:D11) -> 685 | E12: =SUM(E7:E11) -> 685 | F12: =SUM(F7:F11) -> 685 | G12: =SUM(G7:G11) -> 685 | H12: =SUM(H7:H11) -> 685 | I12: =SUM(I7:I11) -> 0 | ... M12: =SUM(M7:M11) -> 0 | O12: =SUM(B12:M12) -> 5095
A13: UBER | B13: 50 | C13: 50 | D13: 50 | E13: 50 | F13: 50 | G13: 50 | H13: 50 | O13: =SUM(B13:M13) -> 350
A14: TRAVEL | B14: 65 | C14: 65 | D14: 65 | E14: 65 | F14: 65 | G14: 65 | H14: 65 | O14: =SUM(B14:M14) -> 455
A15: FOOD | B15: 250 | C15: 250 | D15: 250 | E15: 250 | F15: 250 | G15: 250 | H15: 250 | O15: =SUM(B15:M15) -> 1750
A16: MY PROTIEN | O16: =SUM(B16:M16) -> 0
A17: LUNCH | B17: 90 | C17: 90 | D17: 90 | E17: 90 | F17: 90 | G17: 90 | H17: 90 | O17: =SUM(B17:M17) -> 630
A18: TAKE AWAY | O18: =SUM(B18:M18) -> 0
A19: MONTHLY ALLOWANCE | B19: 200 | C19: 200 | D19: 200 | E19: 200 | F19: 200 | G19: 200 | H19: 200 | O19: =SUM(B19:M19) -> 1400
A20: LAUNDRY | B20: 20 | C20: 20 | D20: 20 | E20: 20 | F20: 20 | G20: 20 | H20: 20 | O20: =SUM(B20:M20) -> 140
A21: TOTAL | B21: =SUM(B7:B20) -> 2045 | C21: =SUM(C7:C20) -> 2045 | D21: =SUM(D7:D20) -> 2045 | E21: =SUM(E7:E20) -> 2045 | F21: =SUM(F7:F20) -> 2045 | G21: =SUM(G7:G20) -> 2045 | H21: =SUM(H7:H20) -> 2045 | I21: =SUM(I13:I20) -> 0 | J21: =SUM(J13:J20) -> 0 | K21: =SUM(K13:K20) -> 0 | L21: =SUM(L13:L20) -> 0 | M21: =SUM(M13:M20) -> 0 | O21: =SUM(B21:M21) -> 14315
A22: GYM | B22: 30 | C22: 30 | H22: 35 | I22: 30 | O22: =SUM(B22:M22) -> 125
A23: SPLICE | B23: 25 | C23: 10 | F23: 35 | L23: 25
A24: PLUG IN ALLIANCE | B24: 25 | C24: 25 | F24: 25
A25: MICROSOFT | B25: 6 | C25: 6 | L25: 8
A26: LINKTREE | F26: 10
A27: APPLE ITUNES | B27: 12 | C27: 12 | H27: 15 | L27: 15
A28: MAILCHIMP | O28: =SUM(B28:M28) -> 0
A29: DRMS | H29: 5 | L29: 5
A30: SPOTIFY | H30: 15
A31: TOTAL | B31: =SUM(B22:B30) -> 98 | C31: =SUM(C22:C30) -> 83 | D31: =SUM(D22:D30) -> 0 | E31: =SUM(E22:E30) -> 0 | F31: =SUM(F22:F30) -> 70 | G31: =SUM(G22:G30) -> 0 | H31: =SUM(H22:H30) -> 70 | I31: =SUM(I22:I30) -> 30 | ... M31: =SUM(M22:M30) -> 0 | O31: =SUM(B31:M31) -> 404
A32: JAYDA | B32: 180 | C32: 180 | D32: 180 | E32: 180 | F32: 180 | G32: 180 | H32: 180 | O32: =SUM(B32:M32) -> 1260
A33: JAYDA ALLOWANCE | B33: 60 | C33: 60 | D33: 60 | E33: 60 | F33: 60 | G33: 60 | H33: 60 | I33: 45 | L33: 60 | O33: =SUM(B33:M33) -> 525
A34: JAYDA SAVING 2 | O34: =SUM(B34:M34) -> 0
A35: JAYDA EXTRA | B35: 50 | C35: 50 | D35: 50 | E35: 50 | F35: 50 | G35: 50 | H35: 50 | O35: =SUM(B35:M35) -> 350
A36: TOTAL | B36: =SUM(B32:B35) -> 290 | C36: =SUM(C32:C35) -> 290 | D36: =SUM(D32:D35) -> 290 | E36: =SUM(E32:E35) -> 290 | F36: =SUM(F32:F35) -> 290 | G36: =SUM(G32:G35) -> 290 | H36: =SUM(H32:H35) -> 290 | I36: =SUM(I32:I35) -> 45 | ... M36: =SUM(M32:M35) -> 0 | O36: =SUM(B36:M36) -> 2135
A37: VANQUIS | O37: =SUM(B37:M37) -> 0
A38: TOTAL | B38: =SUM(B37:B37) -> 0 | C38: =SUM(C37:C37) -> 0 | D38: =SUM(D37:D37) -> 0 | E38: =SUM(E37:E37) -> 0 | F38: =SUM(F37:F37) -> 0 | G38: =SUM(G37:G37) -> 0 | H38: =SUM(H37:H37) -> 0 | I38: =SUM(I37:I37) -> 0 | ... M38: =SUM(M37:M37) -> 0 | O38: =SUM(B38:M38) -> 0
A39: HOLIDAY FLIGHTS | O39: =SUM(B39:M39) -> 0
A40: BARBERS | B40: 60
A41: HOTEL
...

Sheet PERSONAL BUDGET 2023-2024
A1: 2022 | B1: AUGUST | C1: SEPTEMBER | D1: OCTOBER | E1: NOVEMBER | F1: DECEMBER | G1: JANUARY | H1: FEBURARY | I1: MARCH | J1: APRIL | K1: MAY | L1: JUNE | M1: JULY | O1: TOTAL
A3: RENT | O3: =SUM(B3:M3) -> 0
A4: STUDIO RENT | O4: =SUM(B4:M4) -> 0
A5: COUNCIL TAX | O5: =SUM(B5:M5) -> 0
A6: TOTAL | B6: =SUM(B3:B5) -> 0 | C6: =SUM(C3:C5) -> 0 | D6: =SUM(D3:D5) -> 0 | E6: =SUM(E3:E5) -> 0 | F6: =SUM(F3:F5) -> 0 | H6: =SUM(H3:H5) -> 0 | I6: =SUM(I3:I5) -> 0 | J6: =SUM(J3:J5) -> 0 | K6: =SUM(K3:K5) -> 0 | L6: =SUM(L3:L5) -> 0 | M6: =SUM(M3:M5) -> 0 | O6: =SUM(B6:M6) -> 0
A7: EE | H7: 90 | O7: =SUM(B7:M7) -> 90
A8: VIRGIN | O8: =SUM(B8:M8) -> 0
A9: ECLECTRICITY | B9: 100 | H9: 130 | O9: =SUM(B9:M9) -> 230
A10: LIFE INSURANCE | H10: 15 | O10: =SUM(B10:M10) -> 15
B11: =SUM(B7:B10) -> 100 | C11: =SUM(C7:C10) -> 0 | D11: =SUM(D7:D10) -> 0 | E11: =SUM(E7:E10) -> 0 | F11: =SUM(F7:F10) -> 0 | G11: =SUM(G7:G10) -> 0 | H11: =SUM(H7:H10) -> 235 | I11: =SUM(I7:I10) -> 0 | ... M11: =SUM(M7:M10) -> 0 | O11: =SUM(B11:M11) -> 335
A12: UBER | O12: =SUM(B12:M12) -> 0
A13: TRAVEL | O13: =SUM(B13:M13) -> 0
A14: FOOD | O14: =SUM(B14:M14) -> 0
A15: LUNCH | O15: =SUM(B15:M15) -> 0
A16: MONTHLY ALLOWANCE | O16: =SUM(B16:M16) -> 0
A17: PERSONAL TRAINER | O17: =SUM(B17:M17) -> 0
B18: =SUM(B12:B17) -> 0 | C18: =SUM(C12:C17) -> 0 | D18: =SUM(D12:D17) -> 0 | E18: =SUM(E12:E17) -> 0 | F18: =SUM(F12:F17) -> 0 | G18: =SUM(G12:G17) -> 0 | H18: =SUM(H12:H17) -> 0 | I18: =SUM(I12:I17) -> 0 | ... M18: =SUM(M12:M17) -> 0 | O18: =SUM(B18:M18) -> 0
A19: GYM | O19: =SUM(B19:M19) -> 0
A20: SERVER | O20: =SUM(B20:M20) -> 0
A21: SPLICE | B21: 10 | H21: 8 | O21: =SUM(B21:M21) -> 18
A22: SPOTIFY | B22: 15 | H22: 20
A23: PLUG IN ALLIANCE | H23: 15 | O23: =SUM(B23:M23) -> 15
A24: MICROSOFT | O24: =SUM(B24:M24) -> 0
A25: APPLE ITUNES | B25: 12 | H25: 12 | O25: =SUM(B25:M25) -> 24
A26: MixWMasters | B26: 5 | H26: 25 | O26: =SUM(B26:M26) -> 30
A27: ADOBE | O27: =SUM(B27:M27) -> 0
A28: TOTAL | B28: =SUM(B19:B27) -> 42 | C28: =SUM(C19:C27) -> 0 | D28: =SUM(D19:D27) -> 0 | E28: =SUM(E19:E27) -> 0 | F28: =SUM(F19:F27) -> 0 | H28: =SUM(H19:H27) -> 80 | I28: =SUM(I19:I27) -> 0 | J28: =SUM(J19:J27) -> 0 | K28: =SUM(K19:K27) -> 0 | L28: =SUM(L19:L27) -> 0 | M28: =SUM(M19:M27) -> 0 | O28: =SUM(B28:M28) -> 122
A29: JAYDA | O29: =SUM(B29:M29) -> 0
A30: JAYDA ALLOWANCE | B30: 60 | C30: 40 | H30: 100 | O30: =SUM(B30:M30) -> 200
A31: JAYDA SAVING 2 | O31: =SUM(B31:M31) -> 0
A32: JAYDA FRENCH | O32: =SUM(B32:M32) -> 0
A33: JAYDA DANCE | O33: =SUM(B33:M33) -> 0
A34: JAYDA HOLIDAY
A35: JAYDA SCHOOL GEAR
A36: JAYDA CLOTHES
A37: TOTAL | E37: =SUM(E29:E36) -> 0 | O37: =SUM(B37:M37) -> 0
A38: FAMILY
A41: TOTAL | E41: =SUM(E38:E40) -> 0 | F41: =SUM(F38:F40) -> 0 | G41: =SUM(G38:G40) -> 0 | H41: =SUM(H38:H40) -> 0 | I41: =SUM(I38:I40) -> 0 | J41: =SUM(J38:J40) -> 0 | K41: =SUM(K38:K40) -> 0 | L41: =SUM(L38:L40) -> 0 | M41: =SUM(M29:M40) -> 0
A42: TANA
A43: MUMMY
...

Sheet PERSONAL BUDGET 2024-2025
A1: 2025 | B1: AUGUST | C1: SEPTEMBER | D1: OCTOBER | E1: NOVEMBER | F1: DECEMBER | G1: JANUARY | H1: FEBURARY | I1: MARCH | J1: APRIL | K1: MAY | L1: JUNE | M1: JULY | O1: TOTAL
A3: RENT | O3: =SUM(B3:M3) -> 0
A4: STUDIO RENT | O4: =SUM(B4:M4) -> 0
A5: COUNCIL TAX | O5: =SUM(B5:M5) -> 0
A6: TOTAL | B6: =SUM(B3:B5) -> 0 | C6: =SUM(C3:C5) -> 0 | D6: =SUM(D3:D5) -> 0 | E6: =SUM(E3:E5) -> 0 | F6: =SUM(F3:F5) -> 0 | G6: =SUM(G3:G5) -> 0 | H6: =SUM(H3:H5) -> 0 | I6: =SUM(I3:I5) -> 0 | J6: =SUM(J3:J5) -> 0 | L6: =SUM(L3:L5) -> 0 | M6: =SUM(M3:M5) -> 0 | O6: =SUM(B6:M6) -> 0
A7: EE | J7: 55 | O7: =SUM(B7:M7) -> 55
A8: SKY | O8: =SUM(B8:M8) -> 0
A9: ECLECTRICITY | J9: 65 | O9: =SUM(B9:M9) -> 65
A10: APPLICANE INSURANCE | O10: =SUM(B10:M10) -> 0
A11: ZURICH LIFE INSURANCE | O11: =SUM(B11:M11) -> 0
A12: THAMESWATER | O12: =SUM(B12:M12) -> 0
A13: LIFE INSURANCE | J13: 15 | O13: =SUM(B13:M13) -> 15
B14: =SUM(B7:B13) -> 0 | C14: =SUM(C7:C13) -> 0 | D14: =SUM(D7:D13) -> 0 | E14: =SUM(E7:E13) -> 0 | F14: =SUM(F7:F13) -> 0 | G14: =SUM(G7:G13) -> 0 | H14: =SUM(H7:H13) -> 0 | I14: =SUM(I7:I13) -> 0 | J14: =SUM(J7:J13) -> 135 | L14: =SUM(L7:L13) -> 0 | M14: =SUM(M7:M13) -> 0
A15: UBER | J15: 50 | M15: 10 | O15: =SUM(B15:M15) -> 60
A16: TRAVEL | I16: 120 | J16: 120 | L16: 50 | M16: 100 | O16: =SUM(B16:M16) -> 390
A17: FOOD | I17: 150 | J17: 150 | L17: 70 | M17: 60 | O17: =SUM(B17:M17) -> 430
A18: MY PROTIEN
A19: LUNCH | I19: 100 | J19: 100 | L19: 50 | M19: 70 | O19: =SUM(B19:M19) -> 320
A20: MONTHLY ALLOWANCE | I20: 100 | J20: 400 | M20: 300 | O20: =SUM(B20:M20) -> 800
A21: PERSONAL TRAINER | O21: =SUM(B21:M21) -> 0
B22: =SUM(B15:B21) -> 0 | C22: =SUM(C15:C21) -> 0 | D22: =SUM(D15:D21) -> 0 | E22: =SUM(E15:E21) -> 0 | F22: =SUM(F15:F21) -> 0 | G22: =SUM(G15:G21) -> 0 | H22: =SUM(H15:H21) -> 0 | I22: =SUM(I15:I21) -> 470 | J22: =SUM(J15:J21) -> 820 | L22: =SUM(L15:L21) -> 170 | M22: =SUM(M15:M21) -> 540
A23: GYM | I23: 40 | J23: 40 | O23: =SUM(B23:M23) -> 80
A24: SPLICE | J24: 10
A25: SITE GROUND | J25: 50
A26: SPOTIFY | J26: 20
A27: SLATE | J27: 14 | M27: 14
A28: LINKTREE | M28: 5
A29: PLUG IN ALLIANCE
A30: MICROSOFT | I30: 8 | J30: 10 | L30: 6 | M30: 6
A31: APPLE ITUNES | J31: 12
A32: SERATO | I32: 10 | J32: 10 | M32: 10
A33: EXPERIAN | I33: 15 | J33: 15
A34: SNOOP | I34: 5 | J34: 5
A35: OPEN AI
A36: MONZO | I36: 15 | J36: 15 | O36: =SUM(B36:M36) -> 30
A37: REVOLUT | I37: 55 | J37: 55 | L37: 55 | M37: 55 | O37: =SUM(B37:M37) -> 220
A38: TOTAL | B38: =SUM(B23:B37) -> 0 | C38: =SUM(C23:C37) -> 0 | D38: =SUM(D23:D37) -> 0 | E38: =SUM(E23:E37) -> 0 | F38: =SUM(F23:F37) -> 0 | G38: =SUM(G23:G37) -> 0 | H38: =SUM(H23:H37) -> 0 | I38: =SUM(I23:I37) -> 148 | ... M38: =SUM(M23:M37) -> 90 | O38: =SUM(B38:M38) -> 555
A39: JAYDA | O39: =SUM(B39:M39) -> 0
A40: JAYDA ALLOWANCE | J40: 120 | O40: =SUM(B40:M40) -> 120
A41: JAYDA SAVING 2 | O41: =SUM(B41:M41) -> 0
...

Sheet PERSONAL BUDGET 2025-2026
A1: 2025 - 2026 | B1: AUGUST | C1: SEPTEMBER | D1: OCTOBER | E1: NOVEMBER | F1: DECEMBER | G1: JANUARY | I1: FEBURARY | K1: MARCH | M1: APRIL | O1: MAY | Q1: JUNE | S1: JULY | U1: YEAR TOTAL
A3: HOUSING COSTS
A4: RENT | G4: 800 | H4: Not Paid | I4: 1090 | J4: Not Paid | K4: 1090 | L4: Not Paid | M4: 1090 | N4: Not Paid | O4: 1025 | P4: Not Paid | Q4: 1025 | R4: Not Paid | S4: 1175 | U4: =SUM(B4:S4) -> 7295
A5: MORTGAGE | G5: 750 | H5: Paid | I5: 750 | J5: Not Paid | K5: 750 | L5: Not Paid | M5: 750 | N5: Not Paid | O5: 825 | P5: Not Paid | Q5: 825 | R5: Not Paid | S5: 825 | U5: =SUM(B5:S5) -> 5475
A6: COUNCIL TAX | G6: 166 | H6: Not Paid | I6: 166 | J6: Not Paid | K6: 170 | L6: Not Paid | M6: 170 | N6: Not Paid | O6: 170 | P6: Not Paid | Q6: 170 | R6: Not Paid | S6: 170 | U6: =SUM(B6:S6) -> 1182
A7: HONE DECO / REPAIR | C7: =SUM('[1]House DECO & REPAIR 25'!$D$32) -> 0 | G7: 0 | H7: Not Paid | I7: 0 | J7: Not Paid | K7: 0 | L7: Not Paid | M7: 0 | N7: Not Paid | O7: 0 | P7: Not Paid | Q7: 0 | R7: Not Paid | U7: =SUM(B7:S7) -> 0
A8: SUB TOTAL | B8: =SUM(B4:B7) -> 0 | C8: =SUM(C4:C7) -> 0 | D8: =SUM(D4:D7) -> 0 | E8: =SUM(E4:E7) -> 0 | F8: =SUM(F4:F7) -> 0 | G8: =SUM(G4:G7) -> 1716 | I8: =SUM(I4:I7) -> 2006 | K8: =SUM(K4:K7) -> 2010 | M8: =SUM(M4:M7) -> 2010 | O8: =SUM(O4:O7) -> 2020 | Q8: =SUM(Q4:Q7) -> 2020 | S8: =SUM(S4:S7) -> 2170 | U8: =SUM(U4:U7) -> 13952
A9: UTILITIES
A10: EE | G10: 72 | H10: Not Paid | I10: 72 | J10: Not Paid | K10: 72 | L10: Not Paid | M10: 72 | N10: Not Paid | O10: 72 | P10: Not Paid | Q10: 72 | R10: Not Paid | S10: 72 | U10: =SUM(B10:S10) -> 504
A11: SKY | G11: 105 | H11: Paid | I11: 105 | J11: Not Paid | K11: 105 | L11: Not Paid | M11: 105 | N11: Not Paid | O11: 105 | P11: Not Paid | Q11: 105 | R11: Not Paid | S11: 105 | U11: =SUM(B11:S11) -> 735
A12: ECLECTRICITY | H12: Not Paid | I12: 70 | J12: Not Paid | K12: 70 | L12: Not Paid | M12: 70 | N12: Not Paid | O12: 70 | P12: Not Paid | Q12: 70 | R12: Not Paid | S12: 70 | U12: =SUM(B12:S12) -> 420
A13: THAMES WATER | G13: 40 | H13: Paid | I13: 40 | J13: Not Paid | K13: 40 | L13: Not Paid | M13: 40 | N13: Not Paid | O13: 40 | P13: Not Paid | Q13: 40 | R13: Not Paid | S13: 40 | U13: =SUM(B13:S13) -> 280
A14: ZURICH | G14: 15 | H14: Not Paid | I14: 15 | J14: Not Paid | K14: 15 | L14: Not Paid | M14: 15 | N14: Not Paid | O14: 15 | P14: Not Paid | Q14: 15 | R14: Not Paid | S14: 15 | U14: =SUM(B14:S14) -> 105
A15: GAS | G15: 50 | H15: Paid | I15: 50 | J15: Not Paid | K15: 50 | L15: Not Paid | M15: 30 | N15: Not Paid | O15: 30 | P15: Not Paid | Q15: 30 | R15: Not Paid | S15: 30 | U15: =SUM(B15:S15) -> 270
A16: APPLICANE INSURANCE | G16: 25 | H16: Paid | I16: 25 | J16: Not Paid | K16: 25 | L16: Not Paid | M16: 25 | N16: Not Paid | O16: 25 | P16: Not Paid | Q16: 25 | R16: Not Paid | S16: 25 | U16: =SUM(B16:S16) -> 175
A17: LIFE INSURANCE | G17: 15 | H17: Not Paid | I17: 15 | J17: Not Paid | K17: 15 | L17: Not Paid | M17: 15 | N17: Not Paid | O17: 15 | P17: Not Paid | Q17: 15 | R17: Not Paid | S17: 15 | U17: =SUM(B17:S17) -> 105
A18: SUB TOTAL | B18: =SUM(B10:B17) -> 0 | C18: =SUM(C10:C17) -> 0 | D18: =SUM(D10:D17) -> 0 | E18: =SUM(E10:E17) -> 0 | F18: =SUM(F10:F17) -> 0 | G18: =SUM(G10:G17) -> 322 | I18: =SUM(I10:I17) -> 392 | K18: =SUM(K10:K17) -> 392 | M18: =SUM(M10:M17) -> 372 | O18: =SUM(O10:O17) -> 372 | Q18: =SUM(Q10:Q17) -> 372 | S18: =SUM(S10:S17) -> 372 | U18: =SUM(U10:U17) -> 2594
A19: ALLOWANCES
A20: WORK TRAVEL | G20: 60 | H20: Not Paid | I20: 60 | J20: Not Paid | K20: 60 | L20: Not Paid | M20: 60 | N20: Not Paid | O20: 60 | P20: Not Paid | Q20: 60 | R20: Not Paid | S20: 60 | U20: =SUM(B20:S20) -> 420
A21: UBER | G21: 20 | H21: Not Paid | I21: 20 | J21: Not Paid | K21: 20 | L21: Not Paid | M21: 20 | N21: Not Paid | O21: 20 | P21: Not Paid | Q21: 20 | R21: Not Paid | S21: 20 | U21: 20
A22: FOOD | G22: 200 | H22: Not Paid | I22: 200 | J22: Not Paid | K22: 200 | L22: Not Paid | M22: 200 | N22: Not Paid | O22: 300 | P22: Not Paid | Q22: 300 | R22: Not Paid | S22: 300 | U22: =SUM(B22:S22) -> 1700
A23: LUNCH | G23: 70 | H23: Not Paid | I23: 70 | J23: Not Paid | K23: 70 | L23: Not Paid | M23: 70 | N23: Not Paid | O23: 70 | P23: Not Paid | Q23: 70 | R23: Not Paid | S23: 70 | U23: =SUM(B23:S23) -> 490
A24: MONTHLY ALLOWANCE | G24: 200 | H24: Not Paid | I24: 150 | J24: Not Paid | K24: 150 | L24: Not Paid | M24: 280 | N24: Not Paid | O24: 100 | P24: Not Paid | Q24: 100 | R24: Not Paid | S24: 100 | U24: =SUM(B24:S24) -> 1080
A25: SUB TOTAL | B25: =SUM(B20:B24) -> 0 | C25: =SUM(C20:C24) -> 0 | D25: =SUM(D20:D24) -> 0 | E25: =SUM(E20:E24) -> 0 | F25: =SUM(F20:F24) -> 0 | G25: =SUM(G20:G24) -> 550 | I25: =SUM(I20:I24) -> 500 | K25: =SUM(K20:K24) -> 500 | M25: =SUM(M20:M24) -> 630 | O25: =SUM(O20:O24) -> 550 | Q25: =SUM(Q20:Q24) -> 550 | S25: =SUM(S20:S24) -> 550 | U25: =SUM(U20:U24) -> 3710
A26: SUBSCRIPTIONS
A27: GYM | G27: 0 | H27: Not Paid | I27: 0 | J27: Not Paid | K27: 0 | L27: Not Paid | M27: 0 | N27: Not Paid | O27: 0 | P27: Not Paid | R27: Not Paid | U27: =SUM(B27:S27) -> 0
A28: SERATO | G28: 10 | H28: Not Paid | I28: 10 | J28: Not Paid | K28: 10 | L28: Not Paid | M28: 10 | N28: Not Paid | O28: 10 | P28: Not Paid | Q28: 10 | R28: Not Paid | S28: 10 | U28: =SUM(B28:S28) -> 70
A29: SPLICE | G29: 10 | H29: Not Paid | I29: 10 | J29: Not Paid | K29: 10 | L29: Not Paid | M29: 10 | N29: Not Paid | O29: 10 | P29: Not Paid | Q29: 10 | R29: Not Paid | S29: 10 | U29: =SUM(B29:S29) -> 70
A30: SITE GROUND | G30: 50 | H30: Not Paid | I30: 50 | J30: Not Paid | K30: 50 | L30: Not Paid | M30: 50 | N30: Not Paid | O30: 50 | P30: Not Paid | Q30: 50 | R30: Not Paid | S30: 50 | U30: =SUM(B30:S30) -> 350
A31: DISNEY PLUS | G31: 5 | H31: Not Paid | I31: 5 | J31: Not Paid | K31: 5 | L31: Not Paid | M31: 5 | N31: Not Paid | O31: 5 | P31: Not Paid | Q31: 5 | R31: Not Paid | S31: 5 | U31: =SUM(B31:S31) -> 35
A32: NETFLIX | G32: 20 | H32: Not Paid | I32: 20 | J32: Not Paid | K32: 20 | L32: Not Paid | M32: 20 | N32: Not Paid | O32: 15 | P32: Not Paid | Q32: 15 | R32: Not Paid | S32: 15 | U32: =SUM(B32:S32) -> 125
A33: SPOTIFY | G33: 20 | H33: Not Paid | I33: 20 | J33: Not Paid | K33: 20 | L33: Not Paid | M33: 20 | N33: Not Paid | O33: 20 | P33: Not Paid | Q33: 20 | R33: Not Paid | S33: 20 | U33: =SUM(B33:S33) -> 140
A34: MICROSOFT | G34: 10 | H34: Not Paid | I34: 10 | J34: Not Paid | K34: 10 | L34: Not Paid | M34: 10 | N34: Not Paid | O34: 10 | P34: Not Paid | Q34: 10 | R34: Not Paid | S34: 10 | U34: =SUM(B34:S34) -> 70
A35: APPLE ITUNES | G35: 12 | H35: Not Paid | I35: 12 | J35: Not Paid | K35: 12 | L35: Not Paid | M35: 12 | N35: Not Paid | O35: 12 | P35: Not Paid | Q35: 12 | R35: Not Paid | S35: 12 | U35: =SUM(B35:S35) -> 84
A36: REVOLUT | G36: 14 | H36: Not Paid | I36: 14 | J36: Not Paid | K36: 14 | L36: Not Paid | M36: 14 | N36: Not Paid | O36: 8 | P36: Not Paid | Q36: 8 | R36: Not Paid | S36: 8 | U36: =SUM(B36:S36) -> 80
A37: SUB TOTAL | B37: =SUM(B27:B36) -> 0 | C37: =SUM(C27:C36) -> 0 | D37: =SUM(D27:D36) -> 0 | E37: =SUM(E27:E36) -> 0 | F37: =SUM(F27:F36) -> 0 | G37: =SUM(G27:G36) -> 151 | I37: =SUM(I27:I36) -> 151 | K37: =SUM(K27:K36) -> 151 | M37: =SUM(M27:M36) -> 151 | O37: =SUM(O27:O36) -> 140 | Q37: =SUM(Q27:Q36) -> 140 | S37: =SUM(S27:S36) -> 140 | U37: =SUM(U27:U36) -> 1024
A38: CHILDCARE
A39: JAYDA | G39: 180 | H39: Paid | I39: 180 | J39: Not Paid | K39: 180 | L39: Not Paid | M39: 180 | N39: Not Paid | O39: 180 | P39: Not Paid | Q39: 180 | R39: Not Paid | S39: 180 | U39: =SUM(B39:S39) -> 1260
A40: JAYDA ALLOWANCE | G40: 100 | H40: Paid | I40: 100 | J40: Not Paid | K40: 100 | L40: Not Paid | M40: 100 | N40: Not Paid | O40: 100 | P40: Not Paid | Q40: 100 | R40: Not Paid | S40: 100 | U40: =SUM(B40:S40) -> 700
A41: JAYDA SAVING 2 | G41: 50 | H41: Paid | I41: 50 | J41: Not Paid | K41: 50 | L41: Not Paid | M41: 50 | N41: Not Paid | O41: 50 | P41: Not Paid | Q41: 50 | R41: Not Paid | S41: 50 | U41: =SUM(B41:S41) -> 350
...

Sheet PERSONAL BUDGET 2026-2027
A1: 2026 - 2027 | B1: AUGUST | C1: SEPTEMBER | D1: OCTOBER | E1: NOVEMBER | F1: DECEMBER | G1: JANUARY | H1: FEBURARY | I1: MARCH | J1: APRIL | K1: MAY | L1: JUNE | M1: JULY | O1: YEAR TOTAL
A3: HOUSING COSTS
A4: RENT | B4: 1110 | C4: 1110 | D4: 1110 | E4: 1110 | F4: 1110 | G4: 1110 | H4: 1110 | I4: 1110 | J4: 1110 | K4: 1110 | L4: 1175 | M4: 1175 | O4: =SUM(B4:M4) -> 13450
A5: MORTGAGE | B5: 825 | C5: 825 | D5: 825 | E5: 825 | F5: 825 | G5: 825 | H5: 825 | I5: 825 | J5: 825 | K5: 825 | L5: 825 | M5: 825 | O5: =SUM(B5:M5) -> 9900
A6: COUNCIL TAX | B6: 170 | C6: 170 | D6: 170 | E6: 170 | F6: 170 | G6: 170 | H6: 170 | I6: 170 | J6: 170 | K6: 170 | L6: 170 | M6: 170 | O6: =SUM(B6:M6) -> 2040
A7: SUB TOTAL | B7: =SUM(B4:B6) -> 2105 | C7: =SUM(C4:C6) -> 2105 | D7: =SUM(D4:D6) -> 2105 | E7: =SUM(E4:E6) -> 2105 | F7: =SUM(F4:F6) -> 2105 | G7: =SUM(G4:G6) -> 2105 | H7: =SUM(H4:H6) -> 2105 | I7: =SUM(I4:I6) -> 2105 | ... M7: =SUM(M4:M6) -> 2170 | O7: =SUM(O4:O6) -> 25390
A8: UTILITIES
A9: EE | B9: 55 | C9: 55 | D9: 55 | E9: 55 | F9: 55 | G9: 55 | H9: 35 | I9: 35 | J9: 35 | K9: 35 | L9: 35 | M9: 35 | O9: =SUM(B9:M9) -> 540
A10: SKY | B10: 135 | C10: 135 | D10: 135 | E10: 135 | F10: 135 | G10: 135 | H10: 135 | I10: 135 | J10: 135 | K10: 160 | L10: 160 | M10: 160 | O10: =SUM(B10:M10) -> 1695
A11: ECLECTRICITY | B11: 70 | C11: 70 | D11: 70 | E11: 70 | F11: 70 | G11: 70 | H11: 70 | I11: 70 | J11: 70 | K11: 70 | L11: 70 | M11: 70 | O11: =SUM(B11:M11) -> 840
A12: THAMES WATER | B12: 40 | C12: 40 | D12: 40 | E12: 40 | F12: 40 | G12: 40 | H12: 40 | I12: 40 | J12: 40 | K12: 40 | L12: 40 | M12: 40 | O12: =SUM(B12:M12) -> 480
A13: ZURICH | B13: 15 | C13: 15 | D13: 15 | E13: 15 | F13: 15 | G13: 15 | H13: 15 | I13: 15 | J13: 15 | K13: 15 | L13: 15 | M13: 15 | O13: =SUM(B13:M13) -> 180
A14: GAS | B14: 30 | C14: 30 | D14: 30 | E14: 30 | F14: 30 | G14: 30 | H14: 30 | I14: 30 | J14: 30 | K14: 30 | L14: 30 | M14: 30 | O14: =SUM(B14:M14) -> 360
A15: APPLICANE INSURANCE | B15: 25 | C15: 25 | D15: 25 | E15: 25 | F15: 25 | G15: 25 | H15: 25 | I15: 25 | J15: 25 | K15: 25 | L15: 25 | M15: 25 | O15: =SUM(B15:M15) -> 300
A16: LIFE INSURANCE | B16: 15 | C16: 15 | D16: 15 | E16: 15 | F16: 15 | G16: 15 | H16: 15 | I16: 15 | J16: 15 | K16: 15 | L16: 15 | M16: 15 | O16: =SUM(B16:M16) -> 180
A17: SUB TOTAL | B17: =SUM(B9:B16) -> 385 | C17: =SUM(C9:C16) -> 385 | D17: =SUM(D9:D16) -> 385 | E17: =SUM(E9:E16) -> 385 | F17: =SUM(F9:F16) -> 385 | G17: =SUM(G9:G16) -> 385 | H17: =SUM(H9:H16) -> 365 | I17: =SUM(I9:I16) -> 365 | ... M17: =SUM(M9:M16) -> 390 | O17: =SUM(O9:O16) -> 4575
A18: ALLOWANCES
A19: WORK TRAVEL | B19: 60 | C19: 60 | D19: 60 | E19: 60 | F19: 60 | G19: 60 | H19: 60 | I19: 60 | J19: 60 | K19: 60 | L19: 60 | M19: 60 | O19: =SUM(B19:M19) -> 720
A20: UBER | B20: 20 | C20: 20 | D20: 20 | E20: 20 | F20: 20 | G20: 20 | H20: 20 | I20: 20 | J20: 20 | K20: 20 | L20: 20 | M20: 20 | O20: 20
A21: FOOD | B21: 200 | C21: 200 | D21: 200 | E21: 200 | F21: 200 | G21: 200 | H21: 200 | I21: 200 | J21: 200 | K21: 300 | L21: 300 | M21: 300 | O21: =SUM(B21:M21) -> 2700
A22: LUNCH | B22: 70 | C22: 70 | D22: 70 | E22: 70 | F22: 70 | G22: 70 | H22: 70 | I22: 70 | J22: 70 | K22: 70 | L22: 70 | M22: 70 | O22: =SUM(B22:M22) -> 840
A23: MONTHLY ALLOWANCE | B23: 250 | C23: 150 | D23: 100 | E23: 150 | F23: 280 | G23: 150 | H23: 150 | I23: 150 | J23: 280 | K23: 100 | L23: 100 | M23: 100 | O23: =SUM(B23:M23) -> 1960
A24: SUB TOTAL | B24: =SUM(B19:B23) -> 600 | C24: =SUM(C19:C23) -> 500 | D24: =SUM(D19:D23) -> 450 | E24: =SUM(E19:E23) -> 500 | F24: =SUM(F19:F23) -> 630 | G24: =SUM(G19:G23) -> 500 | H24: =SUM(H19:H23) -> 500 | I24: =SUM(I19:I23) -> 500 | ... M24: =SUM(M19:M23) -> 550 | O24: =SUM(O19:O23) -> 6240
A25: SUBSCRIPTIONS
A26: GYM | O26: =SUM(B26:M26) -> 0
A27: SERATO | B27: 10 | C27: 10 | D27: 10 | E27: 10 | F27: 10 | G27: 10 | H27: 10 | I27: 10 | J27: 10 | K27: 10 | L27: 10 | M27: 10 | O27: =SUM(B27:M27) -> 120
A28: SPLICE | B28: 10 | C28: 10 | D28: 10 | E28: 10 | F28: 10 | G28: 10 | H28: 10 | I28: 10 | J28: 10 | K28: 10 | L28: 10 | M28: 10 | O28: =SUM(B28:M28) -> 120
A29: SITE GROUND | B29: 50 | C29: 50 | D29: 50 | E29: 50 | F29: 50 | G29: 50 | H29: 50 | I29: 50 | J29: 50 | K29: 50 | L29: 50 | M29: 50 | O29: =SUM(B29:M29) -> 600
A30: DISNEY PLUS | B30: 5 | C30: 5 | D30: 5 | E30: 5 | F30: 5 | G30: 5 | H30: 5 | I30: 5 | J30: 5 | K30: 5 | L30: 5 | M30: 5 | O30: =SUM(B30:M30) -> 60
A31: NETFLIX | B31: 15 | C31: 15 | D31: 15 | E31: 15 | F31: 15 | G31: 15 | H31: 15 | I31: 15 | J31: 15 | K31: 15 | L31: 15 | M31: 15 | O31: =SUM(B31:M31) -> 180
A32: SPOTIFY | B32: 20 | C32: 20 | D32: 20 | E32: 20 | F32: 20 | G32: 20 | H32: 20 | I32: 20 | J32: 20 | K32: 20 | L32: 20 | M32: 20 | O32: =SUM(B32:M32) -> 240
A33: MICROSOFT | B33: 8 | C33: 8 | D33: 8 | E33: 8 | F33: 8 | G33: 8 | H33: 8 | I33: 8 | J33: 8 | K33: 6 | L33: 6 | M33: 6 | O33: =SUM(B33:M33) -> 90
A34: APPLE ITUNES | B34: 12 | C34: 12 | D34: 12 | E34: 12 | F34: 12 | G34: 12 | H34: 12 | I34: 12 | J34: 12 | K34: 12 | L34: 12 | M34: 12 | O34: =SUM(B34:M34) -> 144
A35: REVOLUT | B35: 8 | C35: 8 | D35: 8 | E35: 8 | F35: 8 | G35: 8 | H35: 8 | I35: 8 | J35: 8 | K35: 8 | L35: 8 | M35: 8 | O35: =SUM(B35:M35) -> 96
A36: SUB TOTAL | B36: =SUM(B26:B35) -> 138 | C36: =SUM(C26:C35) -> 138 | D36: =SUM(D26:D35) -> 138 | E36: =SUM(E26:E35) -> 138 | F36: =SUM(F26:F35) -> 138 | G36: =SUM(G26:G35) -> 138 | H36: =SUM(H26:H35) -> 138 | I36: =SUM(I26:I35) -> 138 | ... M36: =SUM(M26:M35) -> 136 | O36: =SUM(O26:O35) -> 1650
A37: CHILDCARE
A38: JAYDA | B38: 180 | C38: 180 | D38: 180 | E38: 180 | F38: 180 | G38: 180 | H38: 180 | I38: 180 | J38: 180 | K38: 180 | L38: 180 | M38: 180 | O38: =SUM(B38:M38) -> 2160
A39: JAYDA ALLOWANCE | B39: 100 | C39: 100 | D39: 100 | E39: 100 | F39: 100 | G39: 100 | H39: 100 | I39: 100 | J39: 100 | K39: 100 | L39: 100 | M39: 100 | O39: =SUM(B39:M39) -> 1200
A40: JAYDA SAVING 2 | B40: 50 | C40: 50 | D40: 50 | E40: 50 | F40: 50 | G40: 50 | H40: 50 | I40: 50 | J40: 50 | K40: 50 | L40: 50 | M40: 50 | O40: =SUM(B40:M40) -> 600
A41: JAYDA DANCE | O41: =SUM(B41:M41) -> 0
...

Sheet PERSONAL BUDGET 2027-2028
A1: 2027 - 2028 | B1: AUGUST | C1: SEPTEMBER | D1: OCTOBER | E1: NOVEMBER | F1: DECEMBER | G1: JANUARY | H1: FEBURARY | I1: MARCH | J1: APRIL | K1: MAY | L1: JUNE | M1: JULY | O1: YEAR TOTAL
A3: HOUSING COSTS
A4: RENT | B4: 1175 | C4: 1175 | D4: 1175 | E4: 1175 | F4: 1175 | G4: 1175 | H4: 1175 | I4: 1175 | J4: 1175 | K4: 1175 | L4: 1200 | M4: 1200 | O4: =SUM(B4:M4) -> 14150
A5: MORTGAGE | B5: 825 | C5: 825 | D5: 825 | E5: 825 | F5: 825 | G5: 825 | H5: 825 | I5: 825 | J5: 825 | K5: 825 | L5: 825 | M5: 825 | O5: =SUM(B5:M5) -> 9900
A6: COUNCIL TAX | B6: 170 | C6: 170 | D6: 170 | E6: 170 | F6: 170 | G6: 170 | H6: 170 | I6: 170 | J6: 170 | K6: 170 | L6: 170 | M6: 170 | O6: =SUM(B6:M6) -> 2040
A7: SUB TOTAL | B7: =SUM(B4:B6) -> 2170 | C7: =SUM(C4:C6) -> 2170 | D7: =SUM(D4:D6) -> 2170 | E7: =SUM(E4:E6) -> 2170 | F7: =SUM(F4:F6) -> 2170 | G7: =SUM(G4:G6) -> 2170 | H7: =SUM(H4:H6) -> 2170 | I7: =SUM(I4:I6) -> 2170 | ... M7: =SUM(M4:M6) -> 2195 | O7: =SUM(O4:O6) -> 26090
A8: UTILITIES
A9: EE | B9: 55 | C9: 55 | D9: 55 | E9: 55 | F9: 55 | G9: 55 | H9: 35 | I9: 35 | J9: 35 | K9: 35 | L9: 35 | M9: 35 | O9: =SUM(B9:M9) -> 540
A10: SKY | B10: 135 | C10: 135 | D10: 135 | E10: 135 | F10: 135 | G10: 135 | H10: 135 | I10: 135 | J10: 135 | K10: 160 | L10: 160 | M10: 160 | O10: =SUM(B10:M10) -> 1695
A11: ECLECTRICITY | B11: 70 | C11: 70 | D11: 70 | E11: 70 | F11: 70 | G11: 70 | H11: 70 | I11: 70 | J11: 70 | K11: 70 | L11: 70 | M11: 70 | O11: =SUM(B11:M11) -> 840
A12: THAMES WATER | B12: 40 | C12: 40 | D12: 40 | E12: 40 | F12: 40 | G12: 40 | H12: 40 | I12: 40 | J12: 40 | K12: 40 | L12: 40 | M12: 40 | O12: =SUM(B12:M12) -> 480
A13: ZURICH | B13: 15 | C13: 15 | D13: 15 | E13: 15 | F13: 15 | G13: 15 | H13: 15 | I13: 15 | J13: 15 | K13: 15 | L13: 15 | M13: 15 | O13: =SUM(B13:M13) -> 180
A14: GAS | B14: 30 | C14: 30 | D14: 30 | E14: 30 | F14: 30 | G14: 30 | H14: 30 | I14: 30 | J14: 30 | K14: 30 | L14: 30 | M14: 30 | O14: =SUM(B14:M14) -> 360
A15: APPLICANE INSURANCE | B15: 25 | C15: 25 | D15: 25 | E15: 25 | F15: 25 | G15: 25 | H15: 25 | I15: 25 | J15: 25 | K15: 25 | L15: 25 | M15: 25 | O15: =SUM(B15:M15) -> 300
A16: LIFE INSURANCE | B16: 15 | C16: 15 | D16: 15 | E16: 15 | F16: 15 | G16: 15 | H16: 15 | I16: 15 | J16: 15 | K16: 15 | L16: 15 | M16: 15 | O16: =SUM(B16:M16) -> 180
A17: SUB TOTAL | B17: =SUM(B9:B16) -> 385 | C17: =SUM(C9:C16) -> 385 | D17: =SUM(D9:D16) -> 385 | E17: =SUM(E9:E16) -> 385 | F17: =SUM(F9:F16) -> 385 | G17: =SUM(G9:G16) -> 385 | H17: =SUM(H9:H16) -> 365 | I17: =SUM(I9:I16) -> 365 | ... M17: =SUM(M9:M16) -> 390 | O17: =SUM(O9:O16) -> 4575
A18: ALLOWANCES
A19: WORK TRAVEL | B19: 60 | C19: 60 | D19: 60 | E19: 60 | F19: 60 | G19: 60 | H19: 60 | I19: 60 | J19: 60 | K19: 60 | L19: 60 | M19: 60 | O19: =SUM(B19:M19) -> 720
A20: UBER | B20: 20 | C20: 20 | D20: 20 | E20: 20 | F20: 20 | G20: 20 | H20: 20 | I20: 20 | J20: 20 | K20: 20 | L20: 20 | M20: 20 | O20: 20
A21: FOOD | B21: 200 | C21: 200 | D21: 200 | E21: 200 | F21: 200 | G21: 200 | H21: 200 | I21: 200 | J21: 200 | K21: 300 | L21: 300 | M21: 300 | O21: =SUM(B21:M21) -> 2700
A22: LUNCH | B22: 70 | C22: 70 | D22: 70 | E22: 70 | F22: 70 | G22: 70 | H22: 70 | I22: 70 | J22: 70 | K22: 70 | L22: 70 | M22: 70 | O22: =SUM(B22:M22) -> 840
A23: MONTHLY ALLOWANCE | B23: 250 | C23: 150 | D23: 100 | E23: 150 | F23: 280 | G23: 150 | H23: 150 | I23: 150 | J23: 280 | K23: 100 | L23: 100 | M23: 100 | O23: =SUM(B23:M23) -> 1960
A24: SUB TOTAL | B24: =SUM(B19:B23) -> 600 | C24: =SUM(C19:C23) -> 500 | D24: =SUM(D19:D23) -> 450 | E24: =SUM(E19:E23) -> 500 | F24: =SUM(F19:F23) -> 630 | G24: =SUM(G19:G23) -> 500 | H24: =SUM(H19:H23) -> 500 | I24: =SUM(I19:I23) -> 500 | ... M24: =SUM(M19:M23) -> 550 | O24: =SUM(O19:O23) -> 6240
A25: SUBSCRIPTIONS
A26: GYM | O26: =SUM(B26:M26) -> 0
A27: SERATO | B27: 10 | C27: 10 | D27: 10 | E27: 10 | F27: 10 | G27: 10 | H27: 10 | I27: 10 | J27: 10 | K27: 10 | L27: 10 | M27: 10 | O27: =SUM(B27:M27) -> 120
A28: SPLICE | B28: 10 | C28: 10 | D28: 10 | E28: 10 | F28: 10 | G28: 10 | H28: 10 | I28: 10 | J28: 10 | K28: 10 | L28: 10 | M28: 10 | O28: =SUM(B28:M28) -> 120
A29: SITE GROUND | B29: 50 | C29: 50 | D29: 50 | E29: 50 | F29: 50 | G29: 50 | H29: 50 | I29: 50 | J29: 50 | K29: 50 | L29: 50 | M29: 50 | O29: =SUM(B29:M29) -> 600
A30: DISNEY PLUS | B30: 5 | C30: 5 | D30: 5 | E30: 5 | F30: 5 | G30: 5 | H30: 5 | I30: 5 | J30: 5 | K30: 5 | L30: 5 | M30: 5 | O30: =SUM(B30:M30) -> 60
A31: NETFLIX | B31: 15 | C31: 15 | D31: 15 | E31: 15 | F31: 15 | G31: 15 | H31: 15 | I31: 15 | J31: 15 | K31: 15 | L31: 15 | M31: 15 | O31: =SUM(B31:M31) -> 180
A32: SPOTIFY | B32: 20 | C32: 20 | D32: 20 | E32: 20 | F32: 20 | G32: 20 | H32: 20 | I32: 20 | J32: 20 | K32: 20 | L32: 20 | M32: 20 | O32: =SUM(B32:M32) -> 240
A33: MICROSOFT | B33: 8 | C33: 8 | D33: 8 | E33: 8 | F33: 8 | G33: 8 | H33: 8 | I33: 8 | J33: 8 | K33: 6 | L33: 6 | M33: 6 | O33: =SUM(B33:M33) -> 90
A34: APPLE ITUNES | B34: 12 | C34: 12 | D34: 12 | E34: 12 | F34: 12 | G34: 12 | H34: 12 | I34: 12 | J34: 12 | K34: 12 | L34: 12 | M34: 12 | O34: =SUM(B34:M34) -> 144
A35: REVOLUT | B35: 8 | C35: 8 | D35: 8 | E35: 8 | F35: 8 | G35: 8 | H35: 8 | I35: 8 | J35: 8 | K35: 8 | L35: 8 | M35: 8 | O35: =SUM(B35:M35) -> 96
A36: SUB TOTAL | B36: =SUM(B26:B35) -> 138 | C36: =SUM(C26:C35) -> 138 | D36: =SUM(D26:D35) -> 138 | E36: =SUM(E26:E35) -> 138 | F36: =SUM(F26:F35) -> 138 | G36: =SUM(G26:G35) -> 138 | H36: =SUM(H26:H35) -> 138 | I36: =SUM(I26:I35) -> 138 | ... M36: =SUM(M26:M35) -> 136 | O36: =SUM(O26:O35) -> 1650
A37: CHILDCARE
A38: JAYDA | B38: 180 | C38: 180 | D38: 180 | E38: 180 | F38: 180 | G38: 180 | H38: 180 | I38: 180 | J38: 180 | K38: 180 | L38: 180 | M38: 180 | O38: =SUM(B38:M38) -> 2160
A39: JAYDA ALLOWANCE | B39: 100 | C39: 100 | D39: 100 | E39: 100 | F39: 100 | G39: 100 | H39: 100 | I39: 100 | J39: 100 | K39: 100 | L39: 100 | M39: 100 | O39: =SUM(B39:M39) -> 1200
A40: JAYDA SAVING 2 | B40: 50 | C40: 50 | D40: 50 | E40: 50 | F40: 50 | G40: 50 | H40: 50 | I40: 50 | J40: 50 | K40: 50 | L40: 50 | M40: 50 | O40: =SUM(B40:M40) -> 600
A41: JAYDA DANCE | O41: =SUM(B41:M41) -> 0
...

Sheet PERSONAL BUDGET 2028-2029
A1: 2028 - 2029 | B1: AUGUST | C1: SEPTEMBER | D1: OCTOBER | E1: NOVEMBER | F1: DECEMBER | G1: JANUARY | H1: FEBURARY | I1: MARCH | J1: APRIL | K1: MAY | L1: JUNE | M1: JULY | O1: YEAR TOTAL
A3: HOUSING COSTS
A4: RENT | B4: 1110 | C4: 1110 | D4: 1110 | E4: 1110 | F4: 1110 | G4: 1110 | H4: 1110 | I4: 1110 | J4: 1110 | K4: 1110 | L4: 1175 | M4: 1175 | O4: =SUM(B4:M4) -> 13450
A5: MORTGAGE | B5: 825 | C5: 825 | D5: 825 | E5: 825 | F5: 825 | G5: 825 | H5: 825 | I5: 825 | J5: 825 | K5: 825 | L5: 825 | M5: 825 | O5: =SUM(B5:M5) -> 9900
A6: COUNCIL TAX | B6: 170 | C6: 170 | D6: 170 | E6: 170 | F6: 170 | G6: 170 | H6: 170 | I6: 170 | J6: 170 | K6: 170 | L6: 170 | M6: 170 | O6: =SUM(B6:M6) -> 2040
A7: SUB TOTAL | B7: =SUM(B4:B6) -> 2105 | C7: =SUM(C4:C6) -> 2105 | D7: =SUM(D4:D6) -> 2105 | E7: =SUM(E4:E6) -> 2105 | F7: =SUM(F4:F6) -> 2105 | G7: =SUM(G4:G6) -> 2105 | H7: =SUM(H4:H6) -> 2105 | I7: =SUM(I4:I6) -> 2105 | ... M7: =SUM(M4:M6) -> 2170 | O7: =SUM(O4:O6) -> 25390
A8: UTILITIES
A9: EE | B9: 55 | C9: 55 | D9: 55 | E9: 55 | F9: 55 | G9: 55 | H9: 35 | I9: 35 | J9: 35 | K9: 35 | L9: 35 | M9: 35 | O9: =SUM(B9:M9) -> 540
A10: SKY | B10: 135 | C10: 135 | D10: 135 | E10: 135 | F10: 135 | G10: 135 | H10: 135 | I10: 135 | J10: 135 | K10: 160 | L10: 160 | M10: 160 | O10: =SUM(B10:M10) -> 1695
A11: ECLECTRICITY | B11: 70 | C11: 70 | D11: 70 | E11: 70 | F11: 70 | G11: 70 | H11: 70 | I11: 70 | J11: 70 | K11: 70 | L11: 70 | M11: 70 | O11: =SUM(B11:M11) -> 840
A12: THAMES WATER | B12: 40 | C12: 40 | D12: 40 | E12: 40 | F12: 40 | G12: 40 | H12: 40 | I12: 40 | J12: 40 | K12: 40 | L12: 40 | M12: 40 | O12: =SUM(B12:M12) -> 480
A13: ZURICH | B13: 15 | C13: 15 | D13: 15 | E13: 15 | F13: 15 | G13: 15 | H13: 15 | I13: 15 | J13: 15 | K13: 15 | L13: 15 | M13: 15 | O13: =SUM(B13:M13) -> 180
A14: GAS | B14: 30 | C14: 30 | D14: 30 | E14: 30 | F14: 30 | G14: 30 | H14: 30 | I14: 30 | J14: 30 | K14: 30 | L14: 30 | M14: 30 | O14: =SUM(B14:M14) -> 360
A15: APPLICANE INSURANCE | B15: 25 | C15: 25 | D15: 25 | E15: 25 | F15: 25 | G15: 25 | H15: 25 | I15: 25 | J15: 25 | K15: 25 | L15: 25 | M15: 25 | O15: =SUM(B15:M15) -> 300
A16: LIFE INSURANCE | B16: 15 | C16: 15 | D16: 15 | E16: 15 | F16: 15 | G16: 15 | H16: 15 | I16: 15 | J16: 15 | K16: 15 | L16: 15 | M16: 15 | O16: =SUM(B16:M16) -> 180
A17: SUB TOTAL | B17: =SUM(B9:B16) -> 385 | C17: =SUM(C9:C16) -> 385 | D17: =SUM(D9:D16) -> 385 | E17: =SUM(E9:E16) -> 385 | F17: =SUM(F9:F16) -> 385 | G17: =SUM(G9:G16) -> 385 | H17: =SUM(H9:H16) -> 365 | I17: =SUM(I9:I16) -> 365 | ... M17: =SUM(M9:M16) -> 390 | O17: =SUM(O9:O16) -> 4575
A18: ALLOWANCES
A19: WORK TRAVEL | B19: 60 | C19: 60 | D19: 60 | E19: 60 | F19: 60 | G19: 60 | H19: 60 | I19: 60 | J19: 60 | K19: 60 | L19: 60 | M19: 60 | O19: =SUM(B19:M19) -> 720
A20: UBER | B20: 20 | C20: 20 | D20: 20 | E20: 20 | F20: 20 | G20: 20 | H20: 20 | I20: 20 | J20: 20 | K20: 20 | L20: 20 | M20: 20 | O20: 20
A21: FOOD | B21: 200 | C21: 200 | D21: 200 | E21: 200 | F21: 200 | G21: 200 | H21: 200 | I21: 200 | J21: 200 | K21: 300 | L21: 300 | M21: 300 | O21: =SUM(B21:M21) -> 2700
A22: LUNCH | B22: 70 | C22: 70 | D22: 70 | E22: 70 | F22: 70 | G22: 70 | H22: 70 | I22: 70 | J22: 70 | K22: 70 | L22: 70 | M22: 70 | O22: =SUM(B22:M22) -> 840
A23: MONTHLY ALLOWANCE | B23: 250 | C23: 150 | D23: 100 | E23: 150 | F23: 280 | G23: 150 | H23: 150 | I23: 150 | J23: 280 | K23: 100 | L23: 100 | M23: 100 | O23: =SUM(B23:M23) -> 1960
A24: SUB TOTAL | B24: =SUM(B19:B23) -> 600 | C24: =SUM(C19:C23) -> 500 | D24: =SUM(D19:D23) -> 450 | E24: =SUM(E19:E23) -> 500 | F24: =SUM(F19:F23) -> 630 | G24: =SUM(G19:G23) -> 500 | H24: =SUM(H19:H23) -> 500 | I24: =SUM(I19:I23) -> 500 | ... M24: =SUM(M19:M23) -> 550 | O24: =SUM(O19:O23) -> 6240
A25: SUBSCRIPTIONS
A26: GYM | O26: =SUM(B26:M26) -> 0
A27: SERATO | B27: 10 | C27: 10 | D27: 10 | E27: 10 | F27: 10 | G27: 10 | H27: 10 | I27: 10 | J27: 10 | K27: 10 | L27: 10 | M27: 10 | O27: =SUM(B27:M27) -> 120
A28: SPLICE | B28: 10 | C28: 10 | D28: 10 | E28: 10 | F28: 10 | G28: 10 | H28: 10 | I28: 10 | J28: 10 | K28: 10 | L28: 10 | M28: 10 | O28: =SUM(B28:M28) -> 120
A29: SITE GROUND | B29: 50 | C29: 50 | D29: 50 | E29: 50 | F29: 50 | G29: 50 | H29: 50 | I29: 50 | J29: 50 | K29: 50 | L29: 50 | M29: 50 | O29: =SUM(B29:M29) -> 600
A30: DISNEY PLUS | B30: 5 | C30: 5 | D30: 5 | E30: 5 | F30: 5 | G30: 5 | H30: 5 | I30: 5 | J30: 5 | K30: 5 | L30: 5 | M30: 5 | O30: =SUM(B30:M30) -> 60
A31: NETFLIX | B31: 15 | C31: 15 | D31: 15 | E31: 15 | F31: 15 | G31: 15 | H31: 15 | I31: 15 | J31: 15 | K31: 15 | L31: 15 | M31: 15 | O31: =SUM(B31:M31) -> 180
A32: SPOTIFY | B32: 20 | C32: 20 | D32: 20 | E32: 20 | F32: 20 | G32: 20 | H32: 20 | I32: 20 | J32: 20 | K32: 20 | L32: 20 | M32: 20 | O32: =SUM(B32:M32) -> 240
A33: MICROSOFT | B33: 8 | C33: 8 | D33: 8 | E33: 8 | F33: 8 | G33: 8 | H33: 8 | I33: 8 | J33: 8 | K33: 6 | L33: 6 | M33: 6 | O33: =SUM(B33:M33) -> 90
A34: APPLE ITUNES | B34: 12 | C34: 12 | D34: 12 | E34: 12 | F34: 12 | G34: 12 | H34: 12 | I34: 12 | J34: 12 | K34: 12 | L34: 12 | M34: 12 | O34: =SUM(B34:M34) -> 144
A35: REVOLUT | B35: 8 | C35: 8 | D35: 8 | E35: 8 | F35: 8 | G35: 8 | H35: 8 | I35: 8 | J35: 8 | K35: 8 | L35: 8 | M35: 8 | O35: =SUM(B35:M35) -> 96
A36: SUB TOTAL | B36: =SUM(B26:B35) -> 138 | C36: =SUM(C26:C35) -> 138 | D36: =SUM(D26:D35) -> 138 | E36: =SUM(E26:E35) -> 138 | F36: =SUM(F26:F35) -> 138 | G36: =SUM(G26:G35) -> 138 | H36: =SUM(H26:H35) -> 138 | I36: =SUM(I26:I35) -> 138 | ... M36: =SUM(M26:M35) -> 136 | O36: =SUM(O26:O35) -> 1650
A37: CHILDCARE
A38: JAYDA | O38: =SUM(B38:M38) -> 0
A39: JAYDA ALLOWANCE | B39: 180 | C39: 180 | D39: 180 | E39: 180 | F39: 180 | G39: 180 | H39: 180 | I39: 180 | J39: 180 | K39: 180 | L39: 180 | M39: 180 | O39: =SUM(B39:M39) -> 2160
A40: JAYDA SAVING 2 | B40: 50 | C40: 50 | D40: 50 | E40: 50 | F40: 50 | G40: 50 | H40: 50 | I40: 50 | J40: 50 | K40: 50 | L40: 50 | M40: 50 | O40: =SUM(B40:M40) -> 600
A41: JAYDA DANCE | O41: =SUM(B41:M41) -> 0
...

Sheet PERSONAL BUDGET 2029-2030
A1: 2029 - 2030 | B1: AUGUST | C1: SEPTEMBER | D1: OCTOBER | E1: NOVEMBER | F1: DECEMBER | G1: JANUARY | H1: FEBURARY | I1: MARCH | J1: APRIL | K1: MAY | L1: JUNE | M1: JULY | O1: YEAR TOTAL
A3: HOUSING COSTS
A4: RENT | B4: 1110 | C4: 1110 | D4: 1110 | E4: 1110 | F4: 1110 | G4: 1110 | H4: 1110 | I4: 1110 | J4: 1110 | K4: 1110 | L4: 1175 | M4: 1175 | O4: =SUM(B4:M4) -> 13450
A5: MORTGAGE | B5: 825 | C5: 825 | D5: 825 | E5: 825 | F5: 825 | G5: 825 | H5: 825 | I5: 825 | J5: 825 | K5: 825 | L5: 825 | M5: 825 | O5: =SUM(B5:M5) -> 9900
A6: COUNCIL TAX | B6: 170 | C6: 170 | D6: 170 | E6: 170 | F6: 170 | G6: 170 | H6: 170 | I6: 170 | J6: 170 | K6: 170 | L6: 170 | M6: 170 | O6: =SUM(B6:M6) -> 2040
A7: SUB TOTAL | B7: =SUM(B4:B6) -> 2105 | C7: =SUM(C4:C6) -> 2105 | D7: =SUM(D4:D6) -> 2105 | E7: =SUM(E4:E6) -> 2105 | F7: =SUM(F4:F6) -> 2105 | G7: =SUM(G4:G6) -> 2105 | H7: =SUM(H4:H6) -> 2105 | I7: =SUM(I4:I6) -> 2105 | ... M7: =SUM(M4:M6) -> 2170 | O7: =SUM(O4:O6) -> 25390
A8: UTILITIES
A9: EE | B9: 55 | C9: 55 | D9: 55 | E9: 55 | F9: 55 | G9: 55 | H9: 35 | I9: 35 | J9: 35 | K9: 35 | L9: 35 | M9: 35 | O9: =SUM(B9:M9) -> 540
A10: SKY | B10: 135 | C10: 135 | D10: 135 | E10: 135 | F10: 135 | G10: 135 | H10: 135 | I10: 135 | J10: 135 | K10: 160 | L10: 160 | M10: 160 | O10: =SUM(B10:M10) -> 1695
A11: ECLECTRICITY | B11: 70 | C11: 70 | D11: 70 | E11: 70 | F11: 70 | G11: 70 | H11: 70 | I11: 70 | J11: 70 | K11: 70 | L11: 70 | M11: 70 | O11: =SUM(B11:M11) -> 840
A12: THAMES WATER | B12: 40 | C12: 40 | D12: 40 | E12: 40 | F12: 40 | G12: 40 | H12: 40 | I12: 40 | J12: 40 | K12: 40 | L12: 40 | M12: 40 | O12: =SUM(B12:M12) -> 480
A13: ZURICH | B13: 15 | C13: 15 | D13: 15 | E13: 15 | F13: 15 | G13: 15 | H13: 15 | I13: 15 | J13: 15 | K13: 15 | L13: 15 | M13: 15 | O13: =SUM(B13:M13) -> 180
A14: GAS | B14: 30 | C14: 30 | D14: 30 | E14: 30 | F14: 30 | G14: 30 | H14: 30 | I14: 30 | J14: 30 | K14: 30 | L14: 30 | M14: 30 | O14: =SUM(B14:M14) -> 360
A15: APPLICANE INSURANCE | B15: 25 | C15: 25 | D15: 25 | E15: 25 | F15: 25 | G15: 25 | H15: 25 | I15: 25 | J15: 25 | K15: 25 | L15: 25 | M15: 25 | O15: =SUM(B15:M15) -> 300
A16: LIFE INSURANCE | B16: 15 | C16: 15 | D16: 15 | E16: 15 | F16: 15 | G16: 15 | H16: 15 | I16: 15 | J16: 15 | K16: 15 | L16: 15 | M16: 15 | O16: =SUM(B16:M16) -> 180
A17: SUB TOTAL | B17: =SUM(B9:B16) -> 385 | C17: =SUM(C9:C16) -> 385 | D17: =SUM(D9:D16) -> 385 | E17: =SUM(E9:E16) -> 385 | F17: =SUM(F9:F16) -> 385 | G17: =SUM(G9:G16) -> 385 | H17: =SUM(H9:H16) -> 365 | I17: =SUM(I9:I16) -> 365 | ... M17: =SUM(M9:M16) -> 390 | O17: =SUM(O9:O16) -> 4575
A18: ALLOWANCES
A19: WORK TRAVEL | B19: 60 | C19: 60 | D19: 60 | E19: 60 | F19: 60 | G19: 60 | H19: 60 | I19: 60 | J19: 60 | K19: 60 | L19: 60 | M19: 60 | O19: =SUM(B19:M19) -> 720
A20: UBER | B20: 20 | C20: 20 | D20: 20 | E20: 20 | F20: 20 | G20: 20 | H20: 20 | I20: 20 | J20: 20 | K20: 20 | L20: 20 | M20: 20 | O20: 20
A21: FOOD | B21: 200 | C21: 200 | D21: 200 | E21: 200 | F21: 200 | G21: 200 | H21: 200 | I21: 200 | J21: 200 | K21: 300 | L21: 300 | M21: 300 | O21: =SUM(B21:M21) -> 2700
A22: LUNCH | B22: 70 | C22: 70 | D22: 70 | E22: 70 | F22: 70 | G22: 70 | H22: 70 | I22: 70 | J22: 70 | K22: 70 | L22: 70 | M22: 70 | O22: =SUM(B22:M22) -> 840
A23: MONTHLY ALLOWANCE | B23: 250 | C23: 150 | D23: 100 | E23: 150 | F23: 280 | G23: 150 | H23: 150 | I23: 150 | J23: 280 | K23: 100 | L23: 100 | M23: 100 | O23: =SUM(B23:M23) -> 1960
A24: SUB TOTAL | B24: =SUM(B19:B23) -> 600 | C24: =SUM(C19:C23) -> 500 | D24: =SUM(D19:D23) -> 450 | E24: =SUM(E19:E23) -> 500 | F24: =SUM(F19:F23) -> 630 | G24: =SUM(G19:G23) -> 500 | H24: =SUM(H19:H23) -> 500 | I24: =SUM(I19:I23) -> 500 | ... M24: =SUM(M19:M23) -> 550 | O24: =SUM(O19:O23) -> 6240
A25: SUBSCRIPTIONS
A26: GYM | O26: =SUM(B26:M26) -> 0
A27: SERATO | B27: 10 | C27: 10 | D27: 10 | E27: 10 | F27: 10 | G27: 10 | H27: 10 | I27: 10 | J27: 10 | K27: 10 | L27: 10 | M27: 10 | O27: =SUM(B27:M27) -> 120
A28: SPLICE | B28: 10 | C28: 10 | D28: 10 | E28: 10 | F28: 10 | G28: 10 | H28: 10 | I28: 10 | J28: 10 | K28: 10 | L28: 10 | M28: 10 | O28: =SUM(B28:M28) -> 120
A29: SITE GROUND | B29: 50 | C29: 50 | D29: 50 | E29: 50 | F29: 50 | G29: 50 | H29: 50 | I29: 50 | J29: 50 | K29: 50 | L29: 50 | M29: 50 | O29: =SUM(B29:M29) -> 600
A30: DISNEY PLUS | B30: 8 | C30: 8 | D30: 8 | E30: 8 | F30: 8 | G30: 8 | H30: 8 | I30: 8 | J30: 8 | K30: 8 | L30: 8 | M30: 8 | O30: =SUM(B30:M30) -> 96
A31: NETFLIX | B31: 15 | C31: 15 | D31: 15 | E31: 15 | F31: 15 | G31: 15 | H31: 15 | I31: 15 | J31: 15 | K31: 15 | L31: 15 | M31: 15 | O31: =SUM(B31:M31) -> 180
A32: SPOTIFY | B32: 20 | C32: 20 | D32: 20 | E32: 20 | F32: 20 | G32: 20 | H32: 20 | I32: 20 | J32: 20 | K32: 20 | L32: 20 | M32: 20 | O32: =SUM(B32:M32) -> 240
A33: MICROSOFT | B33: 8 | C33: 8 | D33: 8 | E33: 8 | F33: 8 | G33: 8 | H33: 8 | I33: 8 | J33: 8 | K33: 6 | L33: 6 | M33: 6 | O33: =SUM(B33:M33) -> 90
A34: APPLE ITUNES | B34: 12 | C34: 12 | D34: 12 | E34: 12 | F34: 12 | G34: 12 | H34: 12 | I34: 12 | J34: 12 | K34: 12 | L34: 12 | M34: 12 | O34: =SUM(B34:M34) -> 144
A35: REVOLUT | B35: 8 | C35: 8 | D35: 8 | E35: 8 | F35: 8 | G35: 8 | H35: 8 | I35: 8 | J35: 8 | K35: 8 | L35: 8 | M35: 8 | O35: =SUM(B35:M35) -> 96
A36: SUB TOTAL | B36: =SUM(B26:B35) -> 141 | C36: =SUM(C26:C35) -> 141 | D36: =SUM(D26:D35) -> 141 | E36: =SUM(E26:E35) -> 141 | F36: =SUM(F26:F35) -> 141 | G36: =SUM(G26:G35) -> 141 | H36: =SUM(H26:H35) -> 141 | I36: =SUM(I26:I35) -> 141 | ... M36: =SUM(M26:M35) -> 139 | O36: =SUM(O26:O35) -> 1686
A37: CHILDCARE
A38: JAYDA | O38: =SUM(B38:M38) -> 0
A39: JAYDA ALLOWANCE | B39: 180 | C39: 180 | D39: 180 | E39: 180 | F39: 180 | G39: 180 | H39: 180 | I39: 180 | J39: 180 | K39: 180 | L39: 180 | M39: 180 | O39: =SUM(B39:M39) -> 2160
A40: JAYDA SAVING 2 | B40: 50 | C40: 50 | D40: 50 | E40: 50 | F40: 50 | G40: 50 | H40: 50 | I40: 50 | J40: 50 | K40: 50 | L40: 50 | M40: 50 | O40: =SUM(B40:M40) -> 600
A41: JAYDA DANCE | O41: =SUM(B41:M41) -> 0
...

Sheet YEARLY TOTALS
B2: 2025/2026 | C2: 2026/2027 | D2: 2027/2028 | E2: 2028/2029 | F2: 2029/2030
A4: HOME DEPOSIT | B4: =SUM('PERSONAL BUDGET 2025-2026'!U71) -> 1000 | C4: =SUM('PERSONAL BUDGET 2026-2027'!O65) -> 7200 | D4: =SUM('PERSONAL BUDGET 2027-2028'!O65) -> 8500 | E4: =SUM('PERSONAL BUDGET 2028-2029'!O65) -> 15900 | F4: =SUM('PERSONAL BUDGET 2029-2030'!O65) -> 15900 | G4: =SUM(B4:F4) -> 48500
A5: EMERGENCY | B5: =SUM('PERSONAL BUDGET 2025-2026'!U69) -> 4300 | C5: =SUM('PERSONAL BUDGET 2026-2027'!O63) -> 11900 | D5: =SUM('PERSONAL BUDGET 2027-2028'!O63) -> 11900 | E5: =SUM('PERSONAL BUDGET 2028-2029'!O63) -> 3900 | F5: =SUM('PERSONAL BUDGET 2029-2030'!O63) -> 2700 | G5: =SUM(B5:F5) -> 34700
A6: SAVING | B6: =SUM('PERSONAL BUDGET 2025-2026'!U70) -> 0 | C6: =SUM('PERSONAL BUDGET 2026-2027'!O64) -> 1500 | D6: =SUM('PERSONAL BUDGET 2027-2028'!O64) -> 1500 | E6: =SUM('PERSONAL BUDGET 2028-2029'!O64) -> 2000 | F6: =SUM('PERSONAL BUDGET 2029-2030'!O64) -> 1100 | G6: =SUM(B6:F6) -> 6100
A7: INVESTMENT | B7: =SUM('PERSONAL BUDGET 2025-2026'!U76) -> 150 | C7: =SUM('PERSONAL BUDGET 2026-2027'!O70) -> 600 | D7: =SUM('PERSONAL BUDGET 2027-2028'!O70) -> 600 | E7: =SUM('PERSONAL BUDGET 2028-2029'!O70) -> 600 | F7: =SUM('PERSONAL BUDGET 2029-2030'!O70) -> 600 | G7: =SUM(B7:F7) -> 2550
A10: UNTOUCHED FUNDS | B10: =SUM(B4:B7) -> 5450 | C10: =SUM(C4:C7) -> 21200 | D10: =SUM(D4:D7) -> 22500 | E10: =SUM(E4:E7) -> 22400 | F10: =SUM(F4:F7) -> 20300 | G10: =SUM(B10:F10) -> 91850
A11: INVESTMENT RETURNS | B11: 0 | C11: 0 | D11: 0 | E11: 0 | F11: 0 | G11: =SUM(B11:E11) -> 0
A12: YEAR LEFT OVER | B12: =SUM('PERSONAL BUDGET 2025-2026'!U90) -> 1810 | C12: =SUM('PERSONAL BUDGET 2026-2027'!O80) -> 4855 | D12: =SUM('PERSONAL BUDGET 2027-2028'!O80) -> 6925 | E12: =SUM('PERSONAL BUDGET 2028-2029'!O80) -> 7125 | F12: =SUM('PERSONAL BUDGET 2029-2030'!O80) -> 10989 | G12: =SUM(B12:F12) -> 31704
F13: TOTAL ASSETS | G13: {=SUM(G10:G12-C21-C22-C23-C24)} -> 123554
A18: DEDUCTIONS
B19: WITHDRAWAL | C19: AMOUNT | D19: DATE
B21: HOME DEPOSIT | C21: 0
B22: HOLIDAY | C22: 0
B23: CAR | C23: 0
B24: WEDDING | C24: 0
